Generated new MARZBAN_PANEL_FERNET_KEY: PNLxGDHkEizR2FrYEJBtPcFECbWaShrWVvpuIX8rIgs=
IMPORTANT: Store this key securely, e.g., in your .env file for persistence.
Traceback (most recent call last):
  File "/home/swebot/.local/lib/python3.10/site-packages/pymysql/connections.py", line 649, in connect
    sock = socket.create_connection(
  File "/usr/lib/python3.10/socket.py", line 836, in create_connection
    for res in getaddrinfo(host, port, 0, SOCK_STREAM):
  File "/usr/lib/python3.10/socket.py", line 967, in getaddrinfo
    for res in _socket.getaddrinfo(host, port, family, type, proto, flags):
socket.gaierror: [Errno -5] No address associated with hostname

During handling of the above exception, another exception occurred:

Traceback (most recent call last):
  File "/home/swebot/.local/lib/python3.10/site-packages/sqlalchemy/engine/base.py", line 145, in __init__
    self._dbapi_connection = engine.raw_connection()
  File "/home/swebot/.local/lib/python3.10/site-packages/sqlalchemy/engine/base.py", line 3297, in raw_connection
    return self.pool.connect()
  File "/home/swebot/.local/lib/python3.10/site-packages/sqlalchemy/pool/base.py", line 449, in connect
    return _ConnectionFairy._checkout(self)
  File "/home/swebot/.local/lib/python3.10/site-packages/sqlalchemy/pool/base.py", line 1264, in _checkout
    fairy = _ConnectionRecord.checkout(pool)
  File "/home/swebot/.local/lib/python3.10/site-packages/sqlalchemy/pool/base.py", line 713, in checkout
    rec = pool._do_get()
  File "/home/swebot/.local/lib/python3.10/site-packages/sqlalchemy/pool/impl.py", line 179, in _do_get
    with util.safe_reraise():
  File "/home/swebot/.local/lib/python3.10/site-packages/sqlalchemy/util/langhelpers.py", line 224, in __exit__
    raise exc_value.with_traceback(exc_tb)
  File "/home/swebot/.local/lib/python3.10/site-packages/sqlalchemy/pool/impl.py", line 177, in _do_get
    return self._create_connection()
  File "/home/swebot/.local/lib/python3.10/site-packages/sqlalchemy/pool/base.py", line 390, in _create_connection
    return _ConnectionRecord(self)
  File "/home/swebot/.local/lib/python3.10/site-packages/sqlalchemy/pool/base.py", line 675, in __init__
    self.__connect()
  File "/home/swebot/.local/lib/python3.10/site-packages/sqlalchemy/pool/base.py", line 901, in __connect
    with util.safe_reraise():
  File "/home/swebot/.local/lib/python3.10/site-packages/sqlalchemy/util/langhelpers.py", line 224, in __exit__
    raise exc_value.with_traceback(exc_tb)
  File "/home/swebot/.local/lib/python3.10/site-packages/sqlalchemy/pool/base.py", line 897, in __connect
    self.dbapi_connection = connection = pool._invoke_creator(self)
  File "/home/swebot/.local/lib/python3.10/site-packages/sqlalchemy/engine/create.py", line 646, in connect
    return dialect.connect(*cargs, **cparams)
  File "/home/swebot/.local/lib/python3.10/site-packages/sqlalchemy/engine/default.py", line 625, in connect
    return self.loaded_dbapi.connect(*cargs, **cparams)  # type: ignore[no-any-return]  # NOQA: E501
  File "/home/swebot/.local/lib/python3.10/site-packages/pymysql/connections.py", line 361, in __init__
    self.connect()
  File "/home/swebot/.local/lib/python3.10/site-packages/pymysql/connections.py", line 716, in connect
    raise exc
pymysql.err.OperationalError: (2003, "Can't connect to MySQL server on 'host' ([Errno -5] No address associated with hostname)")

The above exception was the direct cause of the following exception:

Traceback (most recent call last):
  File "/home/swebot/.local/bin/uvicorn", line 8, in <module>
    sys.exit(main())
  File "/usr/local/lib/python3.10/dist-packages/click/core.py", line 1161, in __call__
    return self.main(*args, **kwargs)
  File "/usr/local/lib/python3.10/dist-packages/click/core.py", line 1082, in main
    rv = self.invoke(ctx)
  File "/usr/local/lib/python3.10/dist-packages/click/core.py", line 1443, in invoke
    return ctx.invoke(self.callback, **ctx.params)
  File "/usr/local/lib/python3.10/dist-packages/click/core.py", line 788, in invoke
    return __callback(*args, **kwargs)
  File "/home/swebot/.local/lib/python3.10/site-packages/uvicorn/main.py", line 413, in main
    run(
  File "/home/swebot/.local/lib/python3.10/site-packages/uvicorn/main.py", line 580, in run
    server.run()
  File "/home/swebot/.local/lib/python3.10/site-packages/uvicorn/server.py", line 66, in run
    return asyncio.run(self.serve(sockets=sockets))
  File "/usr/lib/python3.10/asyncio/runners.py", line 44, in run
    return loop.run_until_complete(main)
  File "uvloop/loop.pyx", line 1518, in uvloop.loop.Loop.run_until_complete
  File "/home/swebot/.local/lib/python3.10/site-packages/uvicorn/server.py", line 70, in serve
    await self._serve(sockets)
  File "/home/swebot/.local/lib/python3.10/site-packages/uvicorn/server.py", line 77, in _serve
    config.load()
  File "/home/swebot/.local/lib/python3.10/site-packages/uvicorn/config.py", line 435, in load
    self.loaded_app = import_from_string(self.app)
  File "/home/swebot/.local/lib/python3.10/site-packages/uvicorn/importer.py", line 19, in import_from_string
    module = importlib.import_module(module_str)
  File "/usr/lib/python3.10/importlib/__init__.py", line 126, in import_module
    return _bootstrap._gcd_import(name[level:], package, level)
  File "<frozen importlib._bootstrap>", line 1050, in _gcd_import
  File "<frozen importlib._bootstrap>", line 1027, in _find_and_load
  File "<frozen importlib._bootstrap>", line 1006, in _find_and_load_unlocked
  File "<frozen importlib._bootstrap>", line 688, in _load_unlocked
  File "<frozen importlib._bootstrap_external>", line 883, in exec_module
  File "<frozen importlib._bootstrap>", line 241, in _call_with_frames_removed
  File "/app/marzban_reseller_panel/frontend/main.py", line 24, in <module>
    Base.metadata.create_all(bind=engine)
  File "/home/swebot/.local/lib/python3.10/site-packages/sqlalchemy/sql/schema.py", line 5924, in create_all
    bind._run_ddl_visitor(
  File "/home/swebot/.local/lib/python3.10/site-packages/sqlalchemy/engine/base.py", line 3247, in _run_ddl_visitor
    with self.begin() as conn:
  File "/usr/lib/python3.10/contextlib.py", line 135, in __enter__
    return next(self.gen)
  File "/home/swebot/.local/lib/python3.10/site-packages/sqlalchemy/engine/base.py", line 3237, in begin
    with self.connect() as conn:
  File "/home/swebot/.local/lib/python3.10/site-packages/sqlalchemy/engine/base.py", line 3273, in connect
    return self._connection_cls(self)
  File "/home/swebot/.local/lib/python3.10/site-packages/sqlalchemy/engine/base.py", line 147, in __init__
    Connection._handle_dbapi_exception_noconnection(
  File "/home/swebot/.local/lib/python3.10/site-packages/sqlalchemy/engine/base.py", line 2436, in _handle_dbapi_exception_noconnection
    raise sqlalchemy_exception.with_traceback(exc_info[2]) from e
  File "/home/swebot/.local/lib/python3.10/site-packages/sqlalchemy/engine/base.py", line 145, in __init__
    self._dbapi_connection = engine.raw_connection()
  File "/home/swebot/.local/lib/python3.10/site-packages/sqlalchemy/engine/base.py", line 3297, in raw_connection
    return self.pool.connect()
  File "/home/swebot/.local/lib/python3.10/site-packages/sqlalchemy/pool/base.py", line 449, in connect
    return _ConnectionFairy._checkout(self)
  File "/home/swebot/.local/lib/python3.10/site-packages/sqlalchemy/pool/base.py", line 1264, in _checkout
    fairy = _ConnectionRecord.checkout(pool)
  File "/home/swebot/.local/lib/python3.10/site-packages/sqlalchemy/pool/base.py", line 713, in checkout
    rec = pool._do_get()
  File "/home/swebot/.local/lib/python3.10/site-packages/sqlalchemy/pool/impl.py", line 179, in _do_get
    with util.safe_reraise():
  File "/home/swebot/.local/lib/python3.10/site-packages/sqlalchemy/util/langhelpers.py", line 224, in __exit__
    raise exc_value.with_traceback(exc_tb)
  File "/home/swebot/.local/lib/python3.10/site-packages/sqlalchemy/pool/impl.py", line 177, in _do_get
    return self._create_connection()
  File "/home/swebot/.local/lib/python3.10/site-packages/sqlalchemy/pool/base.py", line 390, in _create_connection
    return _ConnectionRecord(self)
  File "/home/swebot/.local/lib/python3.10/site-packages/sqlalchemy/pool/base.py", line 675, in __init__
    self.__connect()
  File "/home/swebot/.local/lib/python3.10/site-packages/sqlalchemy/pool/base.py", line 901, in __connect
    with util.safe_reraise():
  File "/home/swebot/.local/lib/python3.10/site-packages/sqlalchemy/util/langhelpers.py", line 224, in __exit__
    raise exc_value.with_traceback(exc_tb)
  File "/home/swebot/.local/lib/python3.10/site-packages/sqlalchemy/pool/base.py", line 897, in __connect
    self.dbapi_connection = connection = pool._invoke_creator(self)
  File "/home/swebot/.local/lib/python3.10/site-packages/sqlalchemy/engine/create.py", line 646, in connect
    return dialect.connect(*cargs, **cparams)
  File "/home/swebot/.local/lib/python3.10/site-packages/sqlalchemy/engine/default.py", line 625, in connect
    return self.loaded_dbapi.connect(*cargs, **cparams)  # type: ignore[no-any-return]  # NOQA: E501
  File "/home/swebot/.local/lib/python3.10/site-packages/pymysql/connections.py", line 361, in __init__
    self.connect()
  File "/home/swebot/.local/lib/python3.10/site-packages/pymysql/connections.py", line 716, in connect
    raise exc
sqlalchemy.exc.OperationalError: (pymysql.err.OperationalError) (2003, "Can't connect to MySQL server on 'host' ([Errno -5] No address associated with hostname)")
(Background on this error at: https://sqlalche.me/e/20/e3q8)
